<?xml version="1.0" ?>
<robot name="PRM_components_urdf">
<link name="base_link">
  <inertial>
    <origin rpy="0 0 0" xyz="-0.0839777178129331 0.04440645528739363 0.03211202600509656"/>
    <mass value="0.27584583240478544"/>
    <inertia ixx="0.001046" ixy="-1e-06" ixz="-0.0" iyy="0.000392" iyz="1.1e-05" izz="0.001324"/>
  </inertial>
  <visual>
    <origin rpy="0 0 0" xyz="0 0 0"/>
    <geometry>
      <mesh filename="package://fusion2urdf/PRM_components_urdf/bin_stl/base_link_m-binary.stl"/>
    </geometry>
    <material name="silver">
      <color rgba="1 0 0 1"/>
    </material>
  </visual>
  <collision>
    <origin rpy="0 0 0" xyz="0 0 0"/>
    <geometry>
      <mesh filename="package://fusion2urdf/PRM_components_urdf/bin_stl/base_link_m-binary.stl"/>
    </geometry>
  </collision>
</link>
<link name="bille_porteuse_1">
  <inertial>
    <origin rpy="0 0 0" xyz="9.06219543850284e-15 -4.4075807889565333e-07 -5.0267488027958e-09"/>
    <mass value="0.008419367021437509"/>
    <inertia ixx="0.0" ixy="0.0" ixz="0.0" iyy="0.0" iyz="0.0" izz="0.0"/>
  </inertial>
  <visual>
    <origin rpy="0 0 0" xyz="0.084 -0.13815 -0.005278"/>
    <geometry>
      <mesh filename="package://fusion2urdf/PRM_components_urdf/bin_stl/bille_porteuse_1_m-binary.stl"/>
    </geometry>
    <material name="silver">
      <color rgba="1 0 0 1"/>
    </material>
  </visual>
  <collision>
    <origin rpy="0 0 0" xyz="0.084 -0.13815 -0.005278"/>
    <geometry>
      <mesh filename="package://fusion2urdf/PRM_components_urdf/bin_stl/bille_porteuse_1_m-binary.stl"/>
    </geometry>
  </collision>
</link>
<link name="left_wheel_1">
  <inertial>
    <origin rpy="0 0 0" xyz="0.016848728056798892 5.266257451158347e-06 7.513062202278709e-06"/>
    <mass value="0.05572555972770472"/>
    <inertia ixx="3e-05" ixy="-0.0" ixz="-0.0" iyy="1.9e-05" iyz="-0.0" izz="1.9e-05"/>
  </inertial>
  <visual>
    <origin rpy="0 0 0" xyz="0.029 -0.002194 -0.032408"/>
    <geometry>
      <mesh filename="package://fusion2urdf/PRM_components_urdf/bin_stl/left_wheel_1_m-binary.stl"/>
    </geometry>
    <material name="silver">
      <color rgba="1 0 0 1"/>
    </material>
  </visual>
  <collision>
    <origin rpy="0 0 0" xyz="0.029 -0.002194 -0.032408"/>
    <geometry>
      <mesh filename="package://fusion2urdf/PRM_components_urdf/bin_stl/left_wheel_1_m-binary.stl"/>
    </geometry>
  </collision>
</link>
<link name="right_wheel_3">
  <inertial>
    <origin rpy="0 0 0" xyz="-0.01683997258297837 -7.067395580239062e-06 5.538351484139781e-06"/>
    <mass value="0.055725588971055603"/>
    <inertia ixx="3e-05" ixy="0.0" ixz="-0.0" iyy="1.9e-05" iyz="0.0" izz="1.9e-05"/>
  </inertial>
  <visual>
    <origin rpy="0 0 0" xyz="0.139 -0.002194 -0.032408"/>
    <geometry>
      <mesh filename="package://fusion2urdf/PRM_components_urdf/bin_stl/right_wheel_3_m-binary.stl"/>
    </geometry>
    <material name="silver">
      <color rgba="1 0 0 1"/>
    </material>
  </visual>
  <collision>
    <origin rpy="0 0 0" xyz="0.139 -0.002194 -0.032408"/>
    <geometry>
      <mesh filename="package://fusion2urdf/PRM_components_urdf/bin_stl/right_wheel_3_m-binary.stl"/>
    </geometry>
  </collision>
</link>
<link name="lien_plaque_sup_1">
  <inertial>
    <origin rpy="0 0 0" xyz="-0.039999999999991334 0.06000009548239064 0.03000032830658448"/>
    <mass value="0.016233798346575297"/>
    <inertia ixx="6.3e-05" ixy="-0.0" ixz="0.0" iyy="3.1e-05" iyz="-0.0" izz="8.4e-05"/>
  </inertial>
  <visual>
    <origin rpy="0 0 0" xyz="0.044 -0.008694 -0.051408"/>
    <geometry>
      <mesh filename="package://fusion2urdf/PRM_components_urdf/bin_stl/lien_plaque_sup_1_m-binary.stl"/>
    </geometry>
    <material name="silver">
      <color rgba="1 0 0 1"/>
    </material>
  </visual>
  <collision>
    <origin rpy="0 0 0" xyz="0.044 -0.008694 -0.051408"/>
    <geometry>
      <mesh filename="package://fusion2urdf/PRM_components_urdf/bin_stl/lien_plaque_sup_1_m-binary.stl"/>
    </geometry>
  </collision>
</link>
<link name="plaque_sup_1">
  <inertial>
    <origin rpy="0 0 0" xyz="-0.03999999999999 0.060785568215751755 0.000750328306584766"/>
    <mass value="0.09905330487184344"/>
    <inertia ixx="0.000271" ixy="-0.0" ixz="-0.0" iyy="0.000189" iyz="0.0" izz="0.000459"/>
  </inertial>
  <visual>
    <origin rpy="0 0 0" xyz="0.044 -0.008694 -0.111408"/>
    <geometry>
      <mesh filename="package://fusion2urdf/PRM_components_urdf/bin_stl/plaque_sup_1_m-binary.stl"/>
    </geometry>
    <material name="silver">
      <color rgba="1 0 0 1"/>
    </material>
  </visual>
  <collision>
    <origin rpy="0 0 0" xyz="0.044 -0.008694 -0.111408"/>
    <geometry>
      <mesh filename="package://fusion2urdf/PRM_components_urdf/bin_stl/plaque_sup_1_m-binary.stl"/>
    </geometry>
  </collision>
</link>
<link name="laser_1">
  <inertial>
    <origin rpy="0 0 0" xyz="0.027457135055986237 -0.04006154961359419 0.024727691022917317"/>
    <mass value="0.07305683031313406"/>
    <inertia ixx="6.2e-05" ixy="1e-06" ixz="0.0" iyy="3.2e-05" iyz="-7e-06" izz="7.2e-05"/>
  </inertial>
  <visual>
    <origin rpy="0 0 0" xyz="0.112 -0.130239 -0.112908"/>
    <geometry>
      <mesh filename="package://fusion2urdf/PRM_components_urdf/bin_stl/laser_1_m-binary.stl"/>
    </geometry>
    <material name="silver">
      <color rgba="1 0 0 1"/>
    </material>
  </visual>
  <collision>
    <origin rpy="0 0 0" xyz="0.112 -0.130239 -0.112908"/>
    <geometry>
      <mesh filename="package://fusion2urdf/PRM_components_urdf/bin_stl/laser_1_m-binary.stl"/>
    </geometry>
  </collision>
</link>
<link name="tilt_1">
  <inertial>
    <origin rpy="0 0 0" xyz="0.012530450621509828 -0.003737858709430081 0.008107618754683063"/>
    <mass value="0.0837710951291597"/>
    <inertia ixx="9e-06" ixy="-0.0" ixz="-0.0" iyy="1.2e-05" iyz="1e-06" izz="9e-06"/>
  </inertial>
  <visual>
    <origin rpy="0 0 0" xyz="0.093603 0.066257 -0.082423"/>
    <geometry>
      <mesh filename="package://fusion2urdf/PRM_components_urdf/bin_stl/tilt_1_m-binary.stl"/>
    </geometry>
    <material name="silver">
      <color rgba="1 0 0 1"/>
    </material>
  </visual>
  <collision>
    <origin rpy="0 0 0" xyz="0.093603 0.066257 -0.082423"/>
    <geometry>
      <mesh filename="package://fusion2urdf/PRM_components_urdf/bin_stl/tilt_1_m-binary.stl"/>
    </geometry>
  </collision>
</link>
<link name="camera_1">
  <inertial>
    <origin rpy="0 0 0" xyz="-0.002779820488642018 -0.0006063637095087004 3.8531724794926836e-05"/>
    <mass value="0.0010901216866178827"/>
    <inertia ixx="0.0" ixy="0.0" ixz="-0.0" iyy="0.0" iyz="-0.0" izz="0.0"/>
  </inertial>
  <visual>
    <origin rpy="0 0 0" xyz="0.081607 0.087487 -0.094501"/>
    <geometry>
      <mesh filename="package://fusion2urdf/PRM_components_urdf/bin_stl/camera_1_m-binary.stl"/>
    </geometry>
    <material name="silver">
      <color rgba="1 0 0 1"/>
    </material>
  </visual>
  <collision>
    <origin rpy="0 0 0" xyz="0.081607 0.087487 -0.094501"/>
    <geometry>
      <mesh filename="package://fusion2urdf/PRM_components_urdf/bin_stl/camera_1_m-binary.stl"/>
    </geometry>
  </collision>
</link>
<link name="pan_1">
  <inertial>
    <origin rpy="0 0 0" xyz="-0.0001970129647064084 -0.006971063596799054 0.01387484558911345"/>
    <mass value="0.10221097927434729"/>
    <inertia ixx="1.7e-05" ixy="-0.0" ixz="0.0" iyy="1.4e-05" iyz="3e-06" izz="1.9e-05"/>
  </inertial>
  <visual>
    <origin rpy="0 0 0" xyz="0.084018 0.039106 -0.051732"/>
    <geometry>
      <mesh filename="package://fusion2urdf/PRM_components_urdf/bin_stl/pan_1_m-binary.stl"/>
    </geometry>
    <material name="silver">
      <color rgba="1 0 0 1"/>
    </material>
  </visual>
  <collision>
    <origin rpy="0 0 0" xyz="0.084018 0.039106 -0.051732"/>
    <geometry>
      <mesh filename="package://fusion2urdf/PRM_components_urdf/bin_stl/pan_1_m-binary.stl"/>
    </geometry>
  </collision>
</link>
<joint name="caster" type="Ball">
  <origin rpy="0 0 0" xyz="-0.084 0.13815 0.005278"/>
  <parent link="base_link"/>
  <child link="bille_porteuse_1"/>
</joint>
<transmission name="caster_tran">
  <type>transmission_interface/SimpleTransmission</type>
  <joint name="caster">
    <hardwareInterface>PositionJointInterface</hardwareInterface>
  </joint>
  <actuator name="caster_actr">
    <hardwareInterface>PositionJointInterface</hardwareInterface>
    <mechanicalReduction>1</mechanicalReduction>
  </actuator>
</transmission>
<joint name="rev_left" type="continuous">
  <origin rpy="0 0 0" xyz="-0.029 0.002194 0.032408"/>
  <parent link="base_link"/>
  <child link="left_wheel_1"/>
  <axis xyz="0.01 -0.0 -0.0"/>
</joint>
<transmission name="rev_left_tran">
  <type>transmission_interface/SimpleTransmission</type>
  <joint name="rev_left">
    <hardwareInterface>PositionJointInterface</hardwareInterface>
  </joint>
  <actuator name="rev_left_actr">
    <hardwareInterface>PositionJointInterface</hardwareInterface>
    <mechanicalReduction>1</mechanicalReduction>
  </actuator>
</transmission>
<joint name="rev_right" type="continuous">
  <origin rpy="0 0 0" xyz="-0.139 0.002194 0.032408"/>
  <parent link="base_link"/>
  <child link="right_wheel_3"/>
  <axis xyz="-0.01 0.0 0.0"/>
</joint>
<transmission name="rev_right_tran">
  <type>transmission_interface/SimpleTransmission</type>
  <joint name="rev_right">
    <hardwareInterface>PositionJointInterface</hardwareInterface>
  </joint>
  <actuator name="rev_right_actr">
    <hardwareInterface>PositionJointInterface</hardwareInterface>
    <mechanicalReduction>1</mechanicalReduction>
  </actuator>
</transmission>
<joint name="rigid_plaque_inf" type="fixed">
  <origin rpy="0 0 0" xyz="-0.044 0.008694 0.051408"/>
  <parent link="base_link"/>
  <child link="lien_plaque_sup_1"/>
</joint>
<transmission name="rigid_plaque_inf_tran">
  <type>transmission_interface/SimpleTransmission</type>
  <joint name="rigid_plaque_inf">
    <hardwareInterface>PositionJointInterface</hardwareInterface>
  </joint>
  <actuator name="rigid_plaque_inf_actr">
    <hardwareInterface>PositionJointInterface</hardwareInterface>
    <mechanicalReduction>1</mechanicalReduction>
  </actuator>
</transmission>
<joint name="rigid_plaque_sup" type="fixed">
  <origin rpy="0 0 0" xyz="0.0 0.0 0.06"/>
  <parent link="lien_plaque_sup_1"/>
  <child link="plaque_sup_1"/>
</joint>
<transmission name="rigid_plaque_sup_tran">
  <type>transmission_interface/SimpleTransmission</type>
  <joint name="rigid_plaque_sup">
    <hardwareInterface>PositionJointInterface</hardwareInterface>
  </joint>
  <actuator name="rigid_plaque_sup_actr">
    <hardwareInterface>PositionJointInterface</hardwareInterface>
    <mechanicalReduction>1</mechanicalReduction>
  </actuator>
</transmission>
<joint name="rplidar_joint" type="fixed">
  <origin rpy="0 0 0" xyz="-0.068 0.121545 0.0015"/>
  <parent link="plaque_sup_1"/>
  <child link="laser_1"/>
</joint>
<transmission name="rplidar_joint_tran">
  <type>transmission_interface/SimpleTransmission</type>
  <joint name="rplidar_joint">
    <hardwareInterface>PositionJointInterface</hardwareInterface>
  </joint>
  <actuator name="rplidar_joint_actr">
    <hardwareInterface>PositionJointInterface</hardwareInterface>
    <mechanicalReduction>1</mechanicalReduction>
  </actuator>
</transmission>
<joint name="tilt_joint" type="revolute">
  <origin rpy="0 0 0" xyz="-0.009585 -0.027151 0.030691"/>
  <parent link="pan_1"/>
  <child link="tilt_1"/>
  <axis xyz="-0.01 -5.3e-05 -9e-06"/>
  <limit effort="100" lower="-1.434661" upper="1.434661" velocity="100"/>
</joint>
<transmission name="tilt_joint_tran">
  <type>transmission_interface/SimpleTransmission</type>
  <joint name="tilt_joint">
    <hardwareInterface>PositionJointInterface</hardwareInterface>
  </joint>
  <actuator name="tilt_joint_actr">
    <hardwareInterface>PositionJointInterface</hardwareInterface>
    <mechanicalReduction>1</mechanicalReduction>
  </actuator>
</transmission>
<joint name="rigid_camera" type="fixed">
  <origin rpy="0 0 0" xyz="0.011996 -0.02123 0.012078"/>
  <parent link="tilt_1"/>
  <child link="camera_1"/>
</joint>
<transmission name="rigid_camera_tran">
  <type>transmission_interface/SimpleTransmission</type>
  <joint name="rigid_camera">
    <hardwareInterface>PositionJointInterface</hardwareInterface>
  </joint>
  <actuator name="rigid_camera_actr">
    <hardwareInterface>PositionJointInterface</hardwareInterface>
    <mechanicalReduction>1</mechanicalReduction>
  </actuator>
</transmission>
<joint name="pan_joint" type="revolute">
  <origin rpy="0 0 0" xyz="-0.084018 -0.039106 0.051732"/>
  <parent link="base_link"/>
  <child link="pan_1"/>
  <axis xyz="9e-06 -0.0 -0.01"/>
  <limit effort="100" lower="-1.570796" upper="1.570796" velocity="100"/>
</joint>
<transmission name="pan_joint_tran">
  <type>transmission_interface/SimpleTransmission</type>
  <joint name="pan_joint">
    <hardwareInterface>PositionJointInterface</hardwareInterface>
  </joint>
  <actuator name="pan_joint_actr">
    <hardwareInterface>PositionJointInterface</hardwareInterface>
    <mechanicalReduction>1</mechanicalReduction>
  </actuator>
</transmission>
<gazebo>
  <plugin filename="libgazebo_ros_control.so" name="control"/>
</gazebo>
</robot>
